[2024-04-29T21:45:47.386+0100] {local_task_job_runner.py:120} INFO - ::group::Pre task execution logs
[2024-04-29T21:45:47.400+0100] {taskinstance.py:2073} INFO - Dependencies all met for dep_context=non-requeueable deps ti=<TaskInstance: ETL_NASA_Asteroids_data.Load_into_db manual__2024-04-29T20:45:34.570378+00:00 [queued]>
[2024-04-29T21:45:47.406+0100] {taskinstance.py:2073} INFO - Dependencies all met for dep_context=requeueable deps ti=<TaskInstance: ETL_NASA_Asteroids_data.Load_into_db manual__2024-04-29T20:45:34.570378+00:00 [queued]>
[2024-04-29T21:45:47.406+0100] {taskinstance.py:2303} INFO - Starting attempt 1 of 4
[2024-04-29T21:45:47.420+0100] {taskinstance.py:2327} INFO - Executing <Task(PythonOperator): Load_into_db> on 2024-04-29 20:45:34.570378+00:00
[2024-04-29T21:45:47.425+0100] {standard_task_runner.py:63} INFO - Started process 149387 to run task
[2024-04-29T21:45:47.428+0100] {standard_task_runner.py:90} INFO - Running: ['airflow', 'tasks', 'run', 'ETL_NASA_Asteroids_data', 'Load_into_db', 'manual__2024-04-29T20:45:34.570378+00:00', '--job-id', '11', '--raw', '--subdir', 'DAGS_FOLDER/etl_dag.py', '--cfg-path', '/tmp/tmpkbbab7yt']
[2024-04-29T21:45:47.430+0100] {standard_task_runner.py:91} INFO - Job 11: Subtask Load_into_db
[2024-04-29T21:45:47.459+0100] {task_command.py:426} INFO - Running <TaskInstance: ETL_NASA_Asteroids_data.Load_into_db manual__2024-04-29T20:45:34.570378+00:00 [running]> on host h3n0k-HP-ProBook-450-G7
[2024-04-29T21:45:47.525+0100] {taskinstance.py:2644} INFO - Exporting env vars: AIRFLOW_CTX_DAG_EMAIL='henokagb@gmail.com' AIRFLOW_CTX_DAG_OWNER='airflow' AIRFLOW_CTX_DAG_ID='ETL_NASA_Asteroids_data' AIRFLOW_CTX_TASK_ID='Load_into_db' AIRFLOW_CTX_EXECUTION_DATE='2024-04-29T20:45:34.570378+00:00' AIRFLOW_CTX_TRY_NUMBER='1' AIRFLOW_CTX_DAG_RUN_ID='manual__2024-04-29T20:45:34.570378+00:00'
[2024-04-29T21:45:47.526+0100] {taskinstance.py:430} INFO - ::endgroup::
[2024-04-29T21:45:47.538+0100] {logging_mixin.py:188} INFO - {}
[2024-04-29T21:45:47.549+0100] {taskinstance.py:441} INFO - ::group::Post task execution logs
[2024-04-29T21:45:47.550+0100] {taskinstance.py:2890} ERROR - Task failed with exception
Traceback (most recent call last):
  File "/home/h3n0k/Documents/Repositories/Perso/ETL-Asteroids_data/test_env/lib/python3.8/site-packages/airflow/models/taskinstance.py", line 465, in _execute_task
    result = _execute_callable(context=context, **execute_callable_kwargs)
  File "/home/h3n0k/Documents/Repositories/Perso/ETL-Asteroids_data/test_env/lib/python3.8/site-packages/airflow/models/taskinstance.py", line 432, in _execute_callable
    return execute_callable(context=context, **execute_callable_kwargs)
  File "/home/h3n0k/Documents/Repositories/Perso/ETL-Asteroids_data/test_env/lib/python3.8/site-packages/airflow/models/baseoperator.py", line 400, in wrapper
    return func(self, *args, **kwargs)
  File "/home/h3n0k/Documents/Repositories/Perso/ETL-Asteroids_data/test_env/lib/python3.8/site-packages/airflow/operators/python.py", line 235, in execute
    return_value = self.execute_callable()
  File "/home/h3n0k/Documents/Repositories/Perso/ETL-Asteroids_data/test_env/lib/python3.8/site-packages/airflow/operators/python.py", line 252, in execute_callable
    return self.python_callable(*self.op_args, **self.op_kwargs)
  File "/home/h3n0k/Documents/Repositories/Perso/ETL-Asteroids_data/airflow/dags/etl_dag.py", line 83, in load_into_db
    collection.insert_many(final_data_dict)
  File "/home/h3n0k/Documents/Repositories/Perso/ETL-Asteroids_data/test_env/lib/python3.8/site-packages/pymongo/_csot.py", line 108, in csot_wrapper
    return func(self, *args, **kwargs)
  File "/home/h3n0k/Documents/Repositories/Perso/ETL-Asteroids_data/test_env/lib/python3.8/site-packages/pymongo/collection.py", line 726, in insert_many
    raise TypeError("documents must be a non-empty list")
TypeError: documents must be a non-empty list
[2024-04-29T21:45:47.559+0100] {taskinstance.py:1205} INFO - Marking task as UP_FOR_RETRY. dag_id=ETL_NASA_Asteroids_data, task_id=Load_into_db, execution_date=20240429T204534, start_date=20240429T204547, end_date=20240429T204547
[2024-04-29T21:45:47.572+0100] {standard_task_runner.py:110} ERROR - Failed to execute job 11 for task Load_into_db (documents must be a non-empty list; 149387)
[2024-04-29T21:45:47.599+0100] {local_task_job_runner.py:240} INFO - Task exited with return code 1
[2024-04-29T21:45:47.609+0100] {taskinstance.py:3482} INFO - 0 downstream tasks scheduled from follow-on schedule check
[2024-04-29T21:45:47.610+0100] {local_task_job_runner.py:222} INFO - ::endgroup::
